<?xml version="1.0"?>
<!--
  Copyright 2015 Fadri Furrer, ASL, ETH Zurich, Switzerland
  Copyright 2015 Michael Burri, ASL, ETH Zurich, Switzerland
  Copyright 2015 Mina Kamel, ASL, ETH Zurich, Switzerland
  Copyright 2015 Janosch Nikolic, ASL, ETH Zurich, Switzerland
  Copyright 2015 Markus Achtelik, ASL, ETH Zurich, Switzerland

  Licensed under the Apache License, Version 2.0 (the "License");
  you may not use this file except in compliance with the License.
  You may obtain a copy of the License at

  http://www.apache.org/licenses/LICENSE-2.0

  Unless required by applicable law or agreed to in writing, software
  distributed under the License is distributed on an "AS IS" BASIS,
  WITHOUT WARRANTIES OR CONDITIONS OF ANY KIND, either express or implied.
  See the License for the specific language governing permissions and
  limitations under the License.
-->

<robot xmlns:xacro="http://ros.org/wiki/xacro">
  <!-- Macro for the inertia of a box -->
  <xacro:macro name="box_inertia" params="x y z mass">
    <inertia ixx="${0.0833333 * mass * (y*y + z*z)}" ixy="0.0" ixz="0.0"
      iyy="${0.0833333 * mass * (x*x + z*z)}" iyz="0.0"
      izz="${0.0833333 * mass * (x*x + y*y)}" />
  </xacro:macro>

  <!-- Macro for the inertial properties of a box -->
  <xacro:macro name="box_inertial" params="x y z mass *origin">
    <inertial>
      <mass value="${mass}" />
      <xacro:insert_block name="origin" />
      <xacro:box_inertia x="${x}" y="${y}" z="${z}" mass="${mass}" />
    </inertial>
  </xacro:macro>

  <!-- Main multirotor link -->
  <xacro:macro name="multirotor_base_macro"
    params="robot_namespace mass body_width body_height use_mesh_file mesh_file *inertia">
    <link name="${robot_namespace}/base_link"></link>

    <joint name="${robot_namespace}/base_joint" type="fixed">
      <origin xyz="-5e-6 4e-6 5e-6" rpy="0 0 0" />
      <parent link="${robot_namespace}/base_link" />
      <child link="${robot_namespace}/base_link_inertia" />
    </joint>

    <link name="${robot_namespace}/base_link_inertia">
      <inertial>
        <mass value="${mass}" />  <!-- [kg] -->
        <origin xyz="0 0 0 " />
        <xacro:insert_block name="inertia" />
      </inertial>

      <visual>
        <origin xyz="0 0 0" rpy="0 0 0" />
        <geometry>
          <xacro:if value="${use_mesh_file}">
            <mesh filename="${mesh_file}" scale="1 1 1" />
          </xacro:if>
          <xacro:unless value="${use_mesh_file}">
            <box size="${body_width} ${body_width} ${body_height}"/> <!-- [m] [m] [m] -->
          </xacro:unless>
        </geometry>
      </visual>

      <collision>
        <origin xyz="0 0 0" rpy="0 0 0" />
        <geometry>
          <box size="${body_width} ${body_width} ${body_height}" /> <!-- [m] [m] [m] -->
        </geometry>
      </collision>
    </link>

    <!-- attach multirotor_base_plugin to the base_link -->
    <gazebo>
      <plugin filename="librotors_gazebo_multirotor_base_plugin.so" name="multirotor_base_plugin">
        <robotNamespace>${robot_namespace}</robotNamespace>
        <linkName>${robot_namespace}/base_link</linkName>
        <rotorVelocitySlowdownSim>${rotor_velocity_slowdown_sim}</rotorVelocitySlowdownSim>
      </plugin>
    </gazebo>
  </xacro:macro>
  <!-- Rotor joint and link -->
  <xacro:macro name="vertical_rotor"
    params="robot_namespace suffix direction motor_constant moment_constant parent mass_rotor scale_rotor radius_rotor time_constant_up time_constant_down max_rot_velocity motor_number rotor_drag_coefficient rolling_moment_coefficient color use_own_mesh mesh blade_type *origin *inertia">
    <joint name="${robot_namespace}/rotor_${motor_number}_joint" type="continuous">
      <xacro:insert_block name="origin" />
      <axis xyz="0 0 1" />
      <!-- TODO(ff): not currently set because it's not yet supported -->
      <!-- <limit effort="2000" velocity="${max_rot_velocity}" /> -->
      <parent link="${parent}" />
      <child link="${robot_namespace}/rotor_${motor_number}" />
    </joint>
    <link name="${robot_namespace}/rotor_${motor_number}">
      <inertial>
        <mass value="${mass_rotor}" /> <!-- [kg] -->
        <xacro:insert_block name="inertia" />
      </inertial>
      <visual>
        <geometry>
          <!-- <cylinder length="0.005" radius="${radius_rotor}"/> --> <!-- [m] -->
          <xacro:if value="${use_own_mesh}">
            <mesh filename="${mesh}"
              scale="1 1 1" />
          </xacro:if>
          <xacro:unless value="${use_own_mesh}">
            <mesh filename="$(find nezha_description)/nezha_mini/meshes/rotor_0_link.STL"
              scale="${scale_rotor} ${scale_rotor} ${scale_rotor}" /> <!-- The propeller meshes have a radius of 1m -->
            <!-- <box size="${2*radius_rotor} 0.01 0.005"/> -->
          </xacro:unless>
        </geometry>
      </visual>
      <collision>
        <geometry>
          <cylinder length="0.005" radius="${scale_rotor}" /> <!-- [m] -->
        </geometry>
      </collision>
    </link>
    <gazebo>
  <!-- <plugin name="near_water_effect_plugin" filename="libNearWaterEffectPlugin.so">
    <rotorLinkName>${robot_namespace}/rotor_${motor_number}</rotorLinkName>
    <rotorRadius>${radius_rotor}</rotorRadius>
    <deltaH>0.05</deltaH>
    <rippleModelPath>/home/w/catkin_ws/src/uuv_simulator/uuv_gazebo_worlds/models/water_ripple/water_ripple.sdf</rippleModelPath>
    <rippleModelName>${robot_namespace}/rotor_${motor_number}_water_ripple</rippleModelName>
    <motorNumber>${motor_number}</motorNumber>

  </plugin>-->

      <plugin name="${robot_namespace}_${suffix}_motor_model" filename="libnezha_motor_model.so">
        <waterAnim>false</waterAnim>
<splashThreshold>0.3</splashThreshold>  <!-- d/R -->
            <rippleModelPath>$(find nezha_gazebo)/models/nezha_water_ripple/water_ripple.sdf</rippleModelPath>
  <rippleModelName>surface_ripple_${suffix}</rippleModelName>
        <jointName>${robot_namespace}/rotor_${motor_number}_joint</jointName>
        <linkName>${robot_namespace}/rotor_${motor_number}</linkName>
          <ktGainPubTopic>kt_gain/${motor_number}</ktGainPubTopic>
          <kqGainPubTopic>kq_gain/${motor_number}</kqGainPubTopic>
          <bladeType>${blade_type}</bladeType>           
          <bladeRadius>${radius_rotor}</bladeRadius>    
        <turningDirection>${direction}</turningDirection>
        <timeConstantUp>${time_constant_up}</timeConstantUp>
        <timeConstantDown>${time_constant_down}</timeConstantDown>
        <maxRotVelocity>${max_rot_velocity}</maxRotVelocity>
        <motorConstant>${motor_constant}</motorConstant>
        <momentConstant>${moment_constant}</momentConstant>
        <commandSubTopic>gazebo/command/motor_speed</commandSubTopic>
        <motorNumber>${motor_number}</motorNumber>
        <rotorDragCoefficient>${rotor_drag_coefficient}</rotorDragCoefficient>
        <rollingMomentCoefficient>${rolling_moment_coefficient}</rollingMomentCoefficient>
        <motorSpeedPubTopic>motor_speed/${motor_number}</motorSpeedPubTopic>
        <rotorVelocitySlowdownSim>${rotor_velocity_slowdown_sim}</rotorVelocitySlowdownSim>
      </plugin>
    </gazebo>
    <gazebo reference="${robot_namespace}/rotor_${motor_number}">
      <material>Gazebo/${color}</material>
    </gazebo>
  </xacro:macro>                                          

  <!-- Rotor joint and link -->
  <xacro:macro name="paddle"
    params="robot_namespace parent mass_paddle radius_rotor paddle_number color use_own_mesh mesh rotor_constant dyn_time_constant *origin *inertia" >
    <joint name="${robot_namespace}/paddle_${paddle_number}_joint" type="continuous">
      <xacro:insert_block name="origin" />
      <axis xyz="0 0 0" />
      <parent link="${parent}" />
      <child link="${robot_namespace}/paddle_${paddle_number}" />
    </joint>
    <link name="${robot_namespace}/paddle_${paddle_number}">
      <inertial>
        <mass value="${mass_paddle}" /> <!-- [kg] -->
        <xacro:insert_block name="inertia" />
      </inertial>
      <visual>
        <geometry>
          <!-- <cylinder length="0.005" radius="${radius_rotor}"/> --> <!-- [m] -->
          <xacro:if value="${use_own_mesh}">
            <mesh filename="${mesh}"
              scale="1 1 1" />
          </xacro:if>
          <xacro:unless value="${use_own_mesh}">
            <mesh filename="$(find nezha_description)/nezha_mini/meshes/paddle_${paddle_number}_link.STL"
              scale="${radius_rotor} ${radius_rotor} ${radius_rotor}" /> <!-- The propeller meshes have a radius of 1m -->
            <!-- <box size="${2*radius_rotor} 0.01 0.005"/> -->
          </xacro:unless>
        </geometry>
      </visual>
      <collision>
        <geometry>
          <cylinder length="0.00005" radius="${radius_rotor}" /> <!-- [m] -->
        </geometry>
      </collision>
    </link>
    <gazebo reference="${robot_namespace}/paddle_${paddle_number}">
      <material>Gazebo/${color}</material>
    </gazebo>
    <gazebo>
      <plugin name="${namespace}_${paddle_number}_thruster_model" filename="libuuv_thruster_ros_plugin.so">
        <linkName>${namespace}/paddle_${paddle_number}</linkName>
        <jointName>${namespace}/paddle_${paddle_number}_joint</jointName>
        <thrusterID>${paddle_number}</thrusterID>
      <xacro:rotor_dyn_first_order_macro time_constant="${dyn_time_constant}"/>
      <xacro:thruster_cf_basic_macro rotor_constant="${rotor_constant}"/>
      </plugin>
    </gazebo>
  </xacro:macro>

  <xacro:macro name="rotor_dyn_first_order_macro" params="time_constant">
    <dynamics>
      <type>FirstOrder</type>
      <timeConstant>${time_constant}</timeConstant>
    </dynamics>
  </xacro:macro>
  <xacro:macro name="thruster_cf_basic_macro"
    params="rotor_constant">
    <conversion>
      <type>Basic</type>
      <rotorConstant>${rotor_constant}</rotorConstant>
    </conversion>
  </xacro:macro>




</robot>
