<?xml version="1.0"?>


<robot xmlns:xacro="http://ros.org/wiki/xacro">
  <!-- Macro for the inertia of a box -->
  <xacro:macro name="box_inertia" params="x y z mass">
    <inertia ixx="${0.0833333 * mass * (y*y + z*z)}" ixy="0.0" ixz="0.0"
      iyy="${0.0833333 * mass * (x*x + z*z)}" iyz="0.0"
      izz="${0.0833333 * mass * (x*x + y*y)}" />
  </xacro:macro>

  <!-- Macro for the inertial properties of a box -->
  <xacro:macro name="box_inertial" params="x y z mass *origin">
    <inertial>
      <mass value="${mass}" />
      <xacro:insert_block name="origin" />
      <xacro:box_inertia x="${x}" y="${y}" z="${z}" mass="${mass}" />
    </inertial>
  </xacro:macro>

  <!-- Main multirotor link -->


  <!-- Rotor joint and link -->
  <xacro:macro name="vertical_rotor"
    params="robot_namespace suffix direction motor_constant moment_constant parent mass_rotor radius_rotor time_constant_up time_constant_down max_rot_velocity motor_number rotor_drag_coefficient rolling_moment_coefficient color use_own_mesh mesh *origin *inertia">
    <joint name="${robot_namespace}/rotor_${motor_number}_joint" type="continuous">
      <xacro:insert_block name="origin" />
      <axis xyz="0 0 1" />
      <!-- TODO(ff): not currently set because it's not yet supported -->
      <!-- <limit effort="2000" velocity="${max_rot_velocity}" /> -->
      <parent link="${parent}" />
      <child link="${robot_namespace}/rotor_${motor_number}" />
    </joint>
    <link name="${robot_namespace}/rotor_${motor_number}">
      <inertial>
        <mass value="${mass_rotor}" /> <!-- [kg] -->
        <xacro:insert_block name="inertia" />
      </inertial>
      <visual>
        <geometry>
          <!-- <cylinder length="0.005" radius="${radius_rotor}"/> --> <!-- [m] -->
          <xacro:if value="${use_own_mesh}">
            <mesh filename="${mesh}"
              scale="1 1 1" />
          </xacro:if>
          <xacro:unless value="${use_own_mesh}">
            <mesh filename="package://rotors_description/meshes/propeller_${direction}.dae"
              scale="${radius_rotor} ${radius_rotor} ${radius_rotor}" /> <!-- The propeller meshes have a radius of 1m -->
            <!-- <box size="${2*radius_rotor} 0.01 0.005"/> -->
          </xacro:unless>
        </geometry>
      </visual>
      <collision>
        <geometry>
          <cylinder length="0.005" radius="${radius_rotor}" /> <!-- [m] -->
        </geometry>
      </collision>
    </link>
    <gazebo>
      <plugin name="${robot_namespace}_${suffix}_motor_model" filename="librotors_gazebo_motor_model.so">
        <robotNamespace>${robot_namespace}</robotNamespace>
        <jointName>${robot_namespace}/rotor_${motor_number}_joint</jointName>
        <linkName>${robot_namespace}/rotor_${motor_number}</linkName>
        <turningDirection>${direction}</turningDirection>
        <timeConstantUp>${time_constant_up}</timeConstantUp>
        <timeConstantDown>${time_constant_down}</timeConstantDown>
        <maxRotVelocity>${max_rot_velocity}</maxRotVelocity>
        <motorConstant>${motor_constant}</motorConstant>
        <momentConstant>${moment_constant}</momentConstant>
        <commandSubTopic>gazebo/command/motor_speed</commandSubTopic>
        <motorNumber>${motor_number}</motorNumber>
        <rotorDragCoefficient>${rotor_drag_coefficient}</rotorDragCoefficient>
        <rollingMomentCoefficient>${rolling_moment_coefficient}</rollingMomentCoefficient>
        <motorSpeedPubTopic>motor_speed/${motor_number}</motorSpeedPubTopic>
        <rotorVelocitySlowdownSim>${rotor_velocity_slowdown_sim}</rotorVelocitySlowdownSim>
      </plugin>
    </gazebo>
    <gazebo reference="${robot_namespace}/rotor_${motor_number}">
      <material>Gazebo/${color}</material>
    </gazebo>
  </xacro:macro>
</robot>
